Workbook

Sheet mold_species_dataset
A1: species_name
A2: Stachybotrys chartarum
A3: Stachybotrys chlorohalonata | B3: Stachybotrys | C3: Toxigenic | D3: dark green | E3: black | F3: slimy | G3: patchy | H3: drywall, wallpaper, cellulose | I3: water damaged walls, ceilings | J3: high | K3: 70+ | L3: 20-30 | M3: yes | N3: rare | O3: high | P3: yes | Q3: remove porous materials; correct moisture | R3: black_colony, slimy_texture, water_damage | S3: Sticky water-damage group | T3: high | U3: toxic + allergenic | V3: 48-72+ hrs after sustained wetting | W3: surface/bulk preferred; air may under-represent | X3: no | Y3: dark green, black, slimy, patchy | Z3: porous materials preferred; non-porous growth usually on rare
A4: Aspergillus niger | B4: Aspergillus | C4: Allergenic / Opportunistic | D4: green | E4: gray | F4: powdery | G4: circular | H4: drywall, insulation, dust | I4: HVAC, walls, dust reservoirs | J4: moderate | K4: 60+ | L4: 20-37 | M4: yes | N4: possible via dust | O4: moderate | P4: some strains | Q4: HEPA vacuum + damp wipe if light | R4: green_powdery, round_colony, dusty_growth | S4: Aspergillus/Penicillium-like | T4: low-to-moderate | U4: allergenic + opportunistic infectious | V4: 24-48 hrs with persistent humidity | W4: air + surface/bulk | X4: no | Y4: green, gray, powdery, circular | Z4: porous materials preferred; non-porous growth usually on possible via dust
A5: Aspergillus fumigatus | B5: Aspergillus | C5: Allergenic / Opportunistic | D5: green | E5: gray | F5: powdery | G5: circular | H5: drywall, insulation, dust | I5: HVAC, walls, dust reservoirs | J5: moderate | K5: 60+ | L5: 20-37 | M5: yes | N5: possible via dust | O5: moderate | P5: some strains | Q5: HEPA vacuum + damp wipe if light | R5: green_powdery, round_colony, dusty_growth | S5: Aspergillus/Penicillium-like | T5: low-to-moderate | U5: allergenic + opportunistic infectious | V5: 24-48 hrs with persistent humidity | W5: air + surface/bulk | X5: no | Y5: green, gray, powdery, circular | Z5: porous materials preferred; non-porous growth usually on possible via dust
A6: Aspergillus flavus | B6: Aspergillus | C6: Allergenic / Opportunistic | D6: green | E6: gray | F6: powdery | G6: circular | H6: drywall, insulation, dust | I6: HVAC, walls, dust reservoirs | J6: moderate | K6: 60+ | L6: 20-37 | M6: yes | N6: possible via dust | O6: moderate | P6: some strains | Q6: HEPA vacuum + damp wipe if light | R6: green_powdery, round_colony, dusty_growth | S6: Aspergillus/Penicillium-like | T6: low-to-moderate | U6: allergenic + opportunistic infectious | V6: 24-48 hrs with persistent humidity | W6: air + surface/bulk | X6: no | Y6: green, gray, powdery, circular | Z6: porous materials preferred; non-porous growth usually on possible via dust
A7: Aspergillus versicolor | B7: Aspergillus | C7: Allergenic / Opportunistic | D7: green | E7: gray | F7: powdery | G7: circular | H7: drywall, insulation, dust | I7: HVAC, walls, dust reservoirs | J7: moderate | K7: 60+ | L7: 20-37 | M7: yes | N7: possible via dust | O7: moderate | P7: some strains | Q7: HEPA vacuum + damp wipe if light | R7: green_powdery, round_colony, dusty_growth | S7: Aspergillus/Penicillium-like | T7: low-to-moderate | U7: allergenic + opportunistic infectious | V7: 24-48 hrs with persistent humidity | W7: air + surface/bulk | X7: no | Y7: green, gray, powdery, circular | Z7: porous materials preferred; non-porous growth usually on possible via dust
A8: Aspergillus terreus | B8: Aspergillus | C8: Allergenic / Opportunistic | D8: green | E8: gray | F8: powdery | G8: circular | H8: drywall, insulation, dust | I8: HVAC, walls, dust reservoirs | J8: moderate | K8: 60+ | L8: 20-37 | M8: yes | N8: possible via dust | O8: moderate | P8: some strains | Q8: HEPA vacuum + damp wipe if light | R8: green_powdery, round_colony, dusty_growth | S8: Aspergillus/Penicillium-like | T8: low-to-moderate | U8: allergenic + opportunistic infectious | V8: 24-48 hrs with persistent humidity | W8: air + surface/bulk | X8: no | Y8: green, gray, powdery, circular | Z8: porous materials preferred; non-porous growth usually on possible via dust
A9: Aspergillus ochraceus | B9: Aspergillus | C9: Allergenic / Opportunistic | D9: green | E9: gray | F9: powdery | G9: circular | H9: drywall, insulation, dust | I9: HVAC, walls, dust reservoirs | J9: moderate | K9: 60+ | L9: 20-37 | M9: yes | N9: possible via dust | O9: moderate | P9: some strains | Q9: HEPA vacuum + damp wipe if light | R9: green_powdery, round_colony, dusty_growth | S9: Aspergillus/Penicillium-like | T9: low-to-moderate | U9: allergenic + opportunistic infectious | V9: 24-48 hrs with persistent humidity | W9: air + surface/bulk | X9: no | Y9: green, gray, powdery, circular | Z9: porous materials preferred; non-porous growth usually on possible via dust
A10: Aspergillus sydowii | B10: Aspergillus | C10: Allergenic / Opportunistic | D10: green | E10: gray | F10: powdery | G10: circular | H10: drywall, insulation, dust | I10: HVAC, walls, dust reservoirs | J10: moderate | K10: 60+ | L10: 20-37 | M10: yes | N10: possible via dust | O10: moderate | P10: some strains | Q10: HEPA vacuum + damp wipe if light | R10: green_powdery, round_colony, dusty_growth | S10: Aspergillus/Penicillium-like | T10: low-to-moderate | U10: allergenic + opportunistic infectious | V10: 24-48 hrs with persistent humidity | W10: air + surface/bulk | X10: no | Y10: green, gray, powdery, circular | Z10: porous materials preferred; non-porous growth usually on possible via dust
A11: Aspergillus glaucus | B11: Aspergillus | C11: Allergenic / Opportunistic | D11: green | E11: gray | F11: powdery | G11: circular | H11: drywall, insulation, dust | I11: HVAC, walls, dust reservoirs | J11: moderate | K11: 60+ | L11: 20-37 | M11: yes | N11: possible via dust | O11: moderate | P11: some strains | Q11: HEPA vacuum + damp wipe if light | R11: green_powdery, round_colony, dusty_growth | S11: Aspergillus/Penicillium-like | T11: low-to-moderate | U11: allergenic + opportunistic infectious | V11: 24-48 hrs with persistent humidity | W11: air + surface/bulk | X11: no | Y11: green, gray, powdery, circular | Z11: porous materials preferred; non-porous growth usually on possible via dust
A12: Aspergillus candidus | B12: Aspergillus | C12: Allergenic / Opportunistic | D12: green | E12: gray | F12: powdery | G12: circular | H12: drywall, insulation, dust | I12: HVAC, walls, dust reservoirs | J12: moderate | K12: 60+ | L12: 20-37 | M12: yes | N12: possible via dust | O12: moderate | P12: some strains | Q12: HEPA vacuum + damp wipe if light | R12: green_powdery, round_colony, dusty_growth | S12: Aspergillus/Penicillium-like | T12: low-to-moderate | U12: allergenic + opportunistic infectious | V12: 24-48 hrs with persistent humidity | W12: air + surface/bulk | X12: no | Y12: green, gray, powdery, circular | Z12: porous materials preferred; non-porous growth usually on possible via dust
A13: Aspergillus restrictus | B13: Aspergillus | C13: Allergenic / Opportunistic | D13: green | E13: gray | F13: powdery | G13: circular | H13: drywall, insulation, dust | I13: HVAC, walls, dust reservoirs | J13: moderate | K13: 60+ | L13: 20-37 | M13: yes | N13: possible via dust | O13: moderate | P13: some strains | Q13: HEPA vacuum + damp wipe if light | R13: green_powdery, round_colony, dusty_growth | S13: Aspergillus/Penicillium-like | T13: low-to-moderate | U13: allergenic + opportunistic infectious | V13: 24-48 hrs with persistent humidity | W13: air + surface/bulk | X13: no | Y13: green, gray, powdery, circular | Z13: porous materials preferred; non-porous growth usually on possible via dust
A14: Penicillium chrysogenum | B14: Penicillium | C14: Common indoor | D14: blue green | E14: white | F14: velvety | G14: spreading | H14: carpet, wallpaper, drywall | I14: basements, walls, stored materials | J14: moderate | K14: 60+ | L14: 15-30 | M14: yes | N14: possible via dust | O14: moderate | P14: some strains | Q14: dry area; remove damaged porous material if extensive | R14: blue_green_velvet, diffuse_edges | S14: Aspergillus/Penicillium-like | T14: low-to-moderate | U14: allergenic + opportunistic infectious | V14: 24-48 hrs with persistent humidity | W14: air + surface/bulk | X14: no | Y14: blue green, white, velvety, spreading | Z14: porous materials preferred; non-porous growth usually on possible via dust
... A120: Malassezia furfur | B120: Malassezia | C120: Common indoor | D120: white | E120: gray | F120: powdery | G120: patchy | H120: drywall, wood, dust | I120: bathrooms, basements, HVAC, windows | J120: moderate | K120: 60+ | L120: 15-32 | M120: yes | N120: possible via dust | O120: low to moderate | P120: possible | Q120: clean visible growth, correct moisture, remove wet porous materials if extensive | R120: patchy_growth, discoloration, moisture_associated | S120: Malassezia visual group | T120: moderate | U120: common indoor / allergen potential | V120: 24-48 hrs with persistent humidity | W120: air and/or surface depending on context | X120: no | Y120: white, gray, powdery, patchy | Z120: porous materials preferred; non-porous growth usually on possible via dust

Sheet Summary
A1: Home Health AI Mold Database v7 Full AI Mold Intelligence System – Summary
A2: Executive metrics for Home Health AI / Inspector Gnome.
A3: Total species | B3: =COUNTA(mold_species_dataset!A4:A1000) -> 117 | D3: All homes contain mold spores. The problem is elevated indoor spore levels and/or active colony growth driven by moisture.
A4: Unique genera | B4: 68 | D4: Use moisture + material + visual pattern + lab context together. Never diagnose from color alone.
A5: High moisture species | B5: =COUNTIF(mold_species_dataset!J4:J1000,"high") -> 20 | D5: High-moisture molds are stronger indicators of chronic wet conditions.
A6: Moderate moisture species | B6: =COUNTIF(mold_species_dataset!J4:J1000,"moderate") -> 91 | D6: Moderate-moisture molds may appear with humidity, condensation, HVAC, or intermittent leaks.
A7: Low moisture species | B7: =COUNTIF(mold_species_dataset!J4:J1000,"low") -> 2 | D7: Low-moisture molds may still matter if amplification or susceptible occupants are present.
A8: Known mycotoxin producers | B8: =COUNTIF(mold_species_dataset!P4:P1000,"Yes") -> 0 | D8: Toxin potential increases priority, but risk communication should stay careful and non-medical.
A9: Warning marker species | B9: =COUNTIF(mold_species_dataset!X4:X1000,"Yes") -> 16 | D9: Marker molds can warn of conditions that support Stachybotrys-like growth.
A10: Visual AI labels | B10: =COUNTA('Image Label Taxonomy'!A5:A1000) -> 11 | D10: Image taxonomy powers computer vision labeling and QA.
A11: Early detection signs | B11: =COUNTA('AI Early Detection Signs'!A2:A1000) -> 12 | D11: Early signs help AI catch issues before visible colonies dominate.
A12: Cleaning agent entries | B12: =COUNTA('Cleaning Agents'!A2:A1000) -> 9 | D12: Cleaning guidance should never replace removal of wet, mold-damaged porous materials.
A13: Lab rule rows | B13: =COUNTA('Lab Interpretation Rules'!A5:A1000) -> 24 | D13: Lab interpretation rules anchor the app to real-world mold reporting language.
A14: Real lab data rows | B14: =COUNTA('Real Lab Data Training'!A5:A1000) -> 20 | D14: Real reports improve calibration and reduce overconfident AI claims.
A15: System control scenarios | B15: =COUNTA('Control Center'!A5:A1000) -> 5 | D15: Control scenarios allow quick MVP testing.
A16: Allergenic / Opportunistic | B16: 10
A17: Common indoor | B17: =COUNTIF(mold_species_dataset!C4:C122,A17) -> 71
A18: Dry environment mold | B18: =COUNTIF(mold_species_dataset!C4:C122,A18) -> 4
A19: Fast-growing indoor | B19: =COUNTIF(mold_species_dataset!C4:C122,A19) -> 5
A20: Pathogenic / Water damage mold | B20: =COUNTIF(mold_species_dataset!C4:C122,A20) -> 5
A21: Toxigenic | B21: =COUNTIF(mold_species_dataset!C4:C122,A21) -> 0
A22: Water damage mold | B22: =COUNTIF(mold_species_dataset!C4:C122,A22) -> 12
B23: =COUNTIF(mold_species_dataset!C4:C122,A23) -> 0
A24: New in v5 | B24: Moisture-source classification, room-by-room inspection logic, remediation decision framework, and image-label taxonomy.
A25: Primary benefit | B25: Improves AI triage, makes outputs more explainable, and creates training labels your developer can use for computer vision and workflow logic.
A26: Best use | B26: Pair with v4 decision tree and scoring model so the app can identify likely source, room context, recommended next step, and appropriate wording.
A29: Integrated uploaded files | B29: SanAir analysis report example + Lab Information interpretation guide
A30: What was added | B30: Lab Interpretation Rules sheet, Lab Sample Examples sheet, direct-ID scale, background-density logic, and training-safe sample examples.

Sheet AI Early Detection Signs
A1: sign_name
A2: Micro-speckling
A3: Moisture halo | B3: circular or irregular stain edge around leak path | C3: drywall, plaster | D3: higher if color gradient present | E3: check leak/condensation
A4: Glossy sheen | B4: localized wet reflective patch | C4: paint, wood, caulk | D4: higher with repeated humidity | E4: reduce RH and inspect source
A5: Texture lift | B5: raised or fuzzy surface compared with adjacent area | C5: wallpaper, drywall | D5: higher if edge is irregular | E5: capture macro image and inspect
A6: Concentric rings | B6: ringed colony structure | C6: window trim, caulk | D6: suggestive for Alternaria-like growth | E6: clean/inspect promptly
A7: Velvet patch | B7: matte velvet-like patch | C7: painted surfaces, wood | D7: common in Cladosporium/Alternaria | E7: confirm moisture and sample if needed
A8: Pink-black streaking | B8: pink or black streaks in condensation zones | C8: window tracks, caulk | D8: common for Aureobasidium-like growth | E8: clean and control condensation
A9: Green powder bloom | B9: fine green dust-like bloom | C9: HVAC dust, insulation | D9: common in Aspergillus/Penicillium patterns | E9: use PPE and HEPA clean
A10: Cottony white growth | B10: soft tufted early growth | C10: cellulose materials | D10: higher concern on wet drywall | E10: remove wet porous material
A11: Dark wet-zone patch | B11: dark patch confined to chronically wet area | C11: subfloors, walls | D11: higher concern if slimy | E11: isolate and assess
A12: Pepper vent spotting | B12: speckling around registers | C12: HVAC diffusers, ceiling | D12: higher if repeated after cleaning | E12: inspect ducts and RH
A13: Bubbling paint | B13: surface deformation with discoloration | C13: painted drywall | D13: not mold alone but strong moisture precursor | E13: open wall if persistent

Sheet Cleaning Agents
A1: agent
A2: Dawn dish soap / detergent
A3: Hydrogen peroxide | B3: light staining and surface disinfection support | C3: tile, grout, some hard surfaces | D3: test fabrics and finished wood first | E3: can lighten staining
A4: Vinegar | B4: mild cleaning where appropriate | C4: tile, glass, some non-stone surfaces | D4: avoid natural stone and incompatible finishes | E4: household option, not a substitute for drying
A5: HEPA vacuum | B5: spore capture during cleanup | C5: dry surfaces and surrounding dust | D5: do not use standard vacuum | E5: best paired with damp wipe
A6: Microfiber damp wipe | B6: final wipe after HEPA removal | C6: non-porous surfaces | D6: avoid oversaturating materials | E6: change cloths frequently
A7: Concrobium or similar | B7: post-cleaning control on some surfaces | C7: framing, sheathing, hard surfaces | D7: follow label; not a shortcut for demolition | E7: commonly used in remediation workflows
A8: Botanical antimicrobial | B8: supplemental cleaning | C8: hard surfaces | D8: not a replacement for moisture control | E8: follow label and ventilation guidance
A9: Enzyme cleaner | B9: organic residue removal | C9: some hard surfaces | D9: avoid if incompatible with finish | E9: use only as directed
A10: Discard and replace | B10: saturated porous materials | C10: drywall, insulation, carpet pad | D10: not applicable | E10: best practice for persistent colonization

Sheet Data Dictionary
A1: field_name
A2: species_name
A3: genus | B3: Genus portion of the scientific name | C3: Aspergillus
A4: common_category | B4: Broad indoor relevance grouping | C4: Water damage mold
A5: primary_color | B5: Typical dominant colony color observed visually | C5: dark green
A6: secondary_color | B6: Secondary or maturing color | C6: black
A7: texture | B7: Surface look such as powdery, velvety, slimy, cottony | C7: powdery
A8: growth_pattern | B8: Typical macro colony form or spread pattern | C8: patchy
A9: common_materials | B9: Materials where growth is commonly observed | C9: drywall, wallpaper, cellulose
A10: common_locations | B10: Typical indoor locations | C10: water damaged walls
A11: moisture_requirement | B11: Low, low-to-moderate, moderate, moderate-to-high, or high moisture need | C11: high
A12: humidity_threshold_percent | B12: Rule-of-thumb RH threshold | C12: 70+
A13: temperature_range_c | B13: Typical growth temperature range in Celsius | C13: 20-30
A14: porous_surface_growth | B14: Whether colonization is common on porous materials | C14: yes
... A23: porous_vs_non_porous_logic | B23: Guidance that mold commonly colonizes porous materials; on hard surfaces it often grows on residue. | C23: tile with soap film
A25: New v4 sheets
A26: AI Decision Tree | B26: Decision path guiding app outputs from screening through escalation | C26: Moisture -> colony texture -> substrate -> output class
A27: Risk Scoring Model | B27: Weighted scoring framework that converts visual/context clues into a normalized risk band | C27: Visible moisture score 4, porous substrate score 5
A28: Inspection Language | B28: Audience-specific wording library for homeowners vs professionals | C28: Homeowner: cautious education; Professional: report-ready framing
A30: New v5 sheets
A31: Moisture Source Classification | B31: Reference table linking visible patterns to likely moisture causes and follow-up steps | C31: Use to infer plumbing vs roof vs HVAC vs condensation vs crawlspace
A32: Room Inspection Logic | B32: Room-specific inspection priorities, false positives, and next-step guidance | C32: Bathroom spotting and attic staining require different logic
A33: Remediation Framework | B33: Monitor/clean/inspect/escalate pathways based on severity, substrate, and recurrence | C33: Supports app workflow and messaging
A34: Image Label Taxonomy | B34: Controlled labels for training image annotations and downstream AI outputs | C34: Creates consistent annotation fields for computer vision
A35: Training Annotation Template | B35: Example row structure with helper formulas for data-labeling workflows | C35: Can be handed to annotators or developers as a starter schema
A36: Lab Interpretation Rules | B36: Condenses lab-report logic for air cassettes, background density, direct ID interpretation, and AI-safe cautions | C36: Supports scoring and user messaging
A37: Lab Sample Examples | B37: Example air and direct-ID results structured as rows for training or QA | C37: Exterior baseline vs interior comparison and direct-ID abundance examples
A39: scenario_id | B39: Unique scenario key used to test scoring engine and output logic. | C39: SCN-001
A40: indoor_outdoor_ratio | B40: Indoor spores/m3 divided by outdoor spores/m3 for the same or nearest comparable group. | C40: 1.9x
A41: risk_band | B41: Human-readable bucket produced by scoring engine. | C41: Elevated
A42: recommended_action | B42: Suggested next step based on score and rule checks. | C42: Professional inspection
A43: visual_group | B43: Grouped AI-safe label when species-level precision is not justified visually. | C43: Aspergillus/Penicillium
A44: water_damage_indicator | B44: Relative value describing how strongly a mold suggests chronic moisture or wet cellulose. | C44: High

Sheet Core Mold Logic
A1: Core Mold Logic for Home Health AI / Inspector Gnome
A2: Important principle: all homes have some mold spores. Concern increases when indoor spore levels are elevated versus normal background and/or when active colonies are growing.
A4: rule_id | B4: rule_name | C4: logic_statement | D4: why_it_matters
A5: ML-01 | B5: Background spores are normal | C5: All homes and buildings contain background mold spores. Spore presence alone does not equal contamination. | D5: Prevents false alarms from normal background ecology.
A6: ML-02 | B6: Elevated spores matter | C6: The concern is elevated indoor spore levels, especially when indoor air is meaningfully higher than outdoor/background comparison. | D6: Helps distinguish normal conditions from likely indoor amplification.
A7: ML-03 | B7: Active colony growth is a problem | C7: Visible mold growth or colonization is more important than simple spore presence. | D7: Colonies indicate moisture plus a growth substrate.
A8: ML-04 | B8: Moisture drives amplification | C8: Mold problems require moisture, a food source, and time. | D8: Focuses the AI on leaks, condensation, and chronic dampness.
A9: ML-05 | B9: Porous materials support colonization | C9: Drywall, carpet, insulation, ceiling tile, paper, and wood are common indoor growth substrates. | D9: Improves material-aware risk scoring.
A10: ML-06 | B10: Non-porous surfaces usually host residue growth | C10: When mold appears on glass, tile, metal, or plastic, it is often growing on dust, soap film, or organic residue rather than the surface itself. | D10: Improves explanation quality and cleaning guidance.
A11: ML-07 | B11: Single-species dominance can signal a source | C11: A strongly dominant indoor genus/species compared with background may indicate an indoor growth reservoir. | D11: Useful for interpretation of air-sampling patterns.
A12: ML-08 | B12: Visual evidence should be tied to moisture context | C12: Water stains, bubbling paint, fuzzy edges, and patch growth near wet zones raise confidence of active colonization. | D12: Supports early visual detection rules.
A13: ML-09 | B13: Diagnosis should be framed carefully | C13: AI should report possible active growth, elevated risk, or need for inspection—not claim medical or lab diagnosis from photos alone. | D13: Keeps output credible and safer for users.
A14: ML-10 | B14: Remediation targets source control | C14: Successful cleanup requires moisture correction, source removal, and proper cleaning—not surface treatment alone. | D14: Prevents ineffective advice.

Sheet Interpretation Examples
A1: scenario
A2: Normal background spores
A3: Possible indoor amplification | B3: Aspergillus/Penicillium notably higher indoors than outdoors | C3: Lower outdoor baseline | D3: Possible indoor source; inspect HVAC, wet wall cavities, and dust reservoirs.
A4: Visible colony on wet drywall | B4: Patchy/slimy/fuzzy colony near leak staining | C4: Outdoor comparison not needed for visual concern | D4: Active growth likely; correct moisture and remove contaminated porous material.
A5: Growth on tile or glass | B5: Visible spots on a hard surface with soap film or dust | C5: Outdoor comparison not needed for surface explanation | D5: Likely growth on residue, not the tile/glass itself; clean residue and control moisture.

Sheet AI Decision Tree
A1: Home Health AI – AI Decision Tree
A2: Use this logic to decide whether the app should reassure, monitor, recommend inspection, or recommend remediation language.
A4: Step | B4: Decision Question | C4: If Yes | D4: If No | E4: AI Output Class | F4: Notes
A5: 1 | B5: Is there a visible moisture indicator (stain, halo, sheen, bubbling, condensation)? | C5: Go to Step 2 | D5: Go to Step 3 | E5: Screening | F5: Moisture raises concern even before clear mold texture appears.
A6: 2 | B6: Is there visible colony texture (fuzzy, powdery, slimy, patchy, irregular edge)? | C6: Go to Step 4 | D6: Output = Moisture Concern | E6: Visual Triage | F6: Moisture without visible colony may still warrant monitoring or inspection.
A7: 3 | B7: No obvious moisture. Is the area showing isolated light residue on a hard surface only? | C7: Output = Surface Residue / Monitor | D7: Output = Low Visual Evidence | E7: Reassure / Monitor | F7: Do not overcall contamination without moisture or growth indicators.
A8: 4 | B8: Is the affected surface porous or cellulose-based (drywall, wood, carpet, ceiling tile, insulation)? | C8: Go to Step 5 | D8: Go to Step 6 | E8: Substrate Logic | F8: Active colonization is more significant on porous materials.
A9: 5 | B9: Is the growth area larger than a small isolated spot OR recurring after cleaning? | C9: Output = Elevated Concern | D9: Go to Step 7 | E9: Escalation | F9: Recurring growth suggests ongoing moisture or hidden amplification.
A10: 6 | B10: On hard surface only: is dust, soap film, or organic residue likely present? | C10: Output = Residue-Supported Growth | D10: Output = Needs Human Review | E10: Surface Interpretation | F10: Mold may be feeding on residue, not the non-porous substrate itself.
A11: 7 | B11: Are there multiple indicators together (moisture + colony + odor + recurring issue + occupant complaint)? | C11: Output = High Concern | D11: Output = Moderate Concern | E11: Risk Band | F11: Combined indicators should raise the model’s confidence and recommendation strength.
A14: Output Class | B14: Recommended App Response | C14: Confidence Direction | D14: Suggested CTA
A15: Low Visual Evidence | B15: No clear visual signs of active growth. Encourage moisture prevention and re-check if changes occur. | C15: Low | D15: Monitor and retake photos if area changes
A16: Surface Residue / Monitor | B16: Visible spotting may reflect residue or surface contamination rather than active colonization. | C16: Low–Moderate | D16: Clean residue, reduce humidity, observe recurrence
A17: Moisture Concern | B17: Visible moisture conditions can support future growth even if a colony is not clearly visible yet. | C17: Moderate | D17: Inspect leak or condensation source
A18: Residue-Supported Growth | B18: Visible growth may be occurring on dust, soap film, or organic buildup on a hard surface. | C18: Moderate | D18: Clean residue thoroughly and control moisture
A19: Moderate Concern | B19: Visible patterns are consistent with possible active growth and warrant closer inspection. | C19: Moderate–High | D19: Schedule targeted inspection
A20: Elevated Concern | B20: Patterns suggest likely active growth associated with moisture and a favorable substrate. | C20: High | D20: Inspect promptly; consider limited containment precautions
A21: High Concern | B21: Multiple indicators strongly suggest active indoor amplification and/or ongoing colony growth. | C21: High | D21: Professional inspection and moisture correction recommended
A22: Needs Human Review | B22: Image evidence is mixed or insufficient for a reliable classification. | C22: Variable | D22: Collect more images / in-person review

Sheet Risk Scoring Model
A1: Home Health AI – Weighted Risk Scoring Model
A2: Enter 0–5 scores in the blue cells. Formulas calculate weighted risk, confidence, and suggested inspection posture.
A4: Factor | B4: What it means | C4: Weight | D4: Input Score (0–5) | E4: Weighted Score | F4: Max Weighted | G4: Professional interpretation | H4: Comment
A5: Visible moisture | B5: Leaks, staining, halos, condensation, or wet sheen | C5: 5 | D5: 0 | E5: =C5*D5 -> 0 | F5: =ABS(C5)*5 -> 25 | G5: Higher moisture = stronger colonization potential
A6: Visible colony texture | B6: Fuzzy, powdery, slimy, patchy, irregular edge | C6: 5 | D6: 0 | E6: =C6*D6 -> 0 | F6: =ABS(C6)*5 -> 25 | G6: Texture is one of the strongest visual indicators
A7: Porous substrate | B7: Drywall, carpet, wood, insulation, ceiling tile | C7: 4 | D7: 0 | E7: =C7*D7 -> 0 | F7: =ABS(C7)*5 -> 20 | G7: Porous materials increase active-growth concern
A8: Area size / spread | B8: Larger or expanding growth footprint | C8: 4 | D8: 0 | E8: =C8*D8 -> 0 | F8: =ABS(C8)*5 -> 20 | G8: Bigger or spreading areas raise urgency
A9: Recurrence after cleaning | B9: Returns after wipe-down or prior treatment | C9: 5 | D9: 0 | E9: =C9*D9 -> 0 | F9: =ABS(C9)*5 -> 25 | G9: Recurrence suggests ongoing moisture or hidden source
A10: Odor / complaint signal | B10: Musty odor, respiratory complaint, occupant concern | C10: 3 | D10: 0 | E10: =C10*D10 -> 0 | F10: =ABS(C10)*5 -> 15 | G10: Supportive but not diagnostic on its own
A11: Indoor > outdoor signal | B11: Air sample or field evidence suggests indoor amplification | C11: 5 | D11: 0 | E11: =C11*D11 -> 0 | F11: =ABS(C11)*5 -> 25 | G11: Useful when spore data exists
A12: Hard-surface residue only | B12: Spots only on tile/glass/metal with soap film or dust | C12: -3 | D12: 0 | E12: =C12*D12 -> 0 | F12: =ABS(C12)*5 -> 15 | G12: This should reduce the score when residue explains the image
A14: Total weighted score | B14: =SUM(E5:E12) -> 0 | D14: Scenario | E14: Sample score | F14: Interpretation | G14: Use case
A15: Maximum possible score | B15: =SUM(F5:F12) -> 170 | D15: Dry tile spotting only | E15: Low–Guarded | F15: Often residue-supported, especially without moisture source | G15: Bathroom hard surface
A16: Normalized risk % | B16: =IF(B15=0,0,(B14+B15)/(2*B15)) -> 0.5 | D16: Wet drywall with texture lift | E16: Elevated–High | F16: Moisture plus porous material plus visible texture | G16: Leak-related room
A17: Risk band | B17: =IF(B16<0.25,"Low",IF(B16<0.45,"Guarded / Monitor",IF(B16<0.65,"Moderate",IF(B16<0.8,"Elevated","High")))) -> Moderate | D17: Musty odor + recurring closet spotting | E17: Moderate–High | F17: Recurring pattern raises suspicion of hidden source | G17: Closet or HVAC adjacent wall
A18: Suggested action | B18: =IF(B17="Low","Educate and monitor",IF(B17="Guarded / Monitor","Clean residue / control humidity / recheck",IF(B17="Moderate","Recommend targeted inspection",IF(B17="Elevated","Prompt inspection and moisture correction","Professional inspection and remediation-oriented language")))) -> Recommend targeted inspection | D18: No texture, no moisture, faint discoloration | E18: Low | F18: Visual evidence weak; monitor and retake images | G18: General screening
A19: Homeowner wording strength | B19: =IF(B17="Low","Reassuring",IF(B17="Guarded / Monitor","Cautious",IF(B17="Moderate","Balanced concern",IF(B17="Elevated","Direct concern","Strong concern")))) -> Balanced concern
A20: Professional wording strength | B20: =IF(B17="Low","Background / no strong visual evidence",IF(B17="Guarded / Monitor","Monitor for recurrence",IF(B17="Moderate","Possible active growth",IF(B17="Elevated","Likely active growth","High suspicion for active amplification")))) -> Possible active growth

Sheet Inspection Language
A1: Home Health AI – Inspection Language by Audience
A2: Separate homeowner language from professional language so the app stays accurate, calm, and credible.
A4: Situation | B4: Audience | C4: Recommended wording | D4: Avoid wording | E4: Purpose | F4: Example app message
A5: No clear evidence | B5: Homeowner | C5: No clear visual signs of active mold growth are visible in this image. | D5: You definitely do not have mold. | E5: Avoid false certainty | F5: We do not see strong visual evidence of active growth in this photo. Keep the area dry and recheck if it changes.
A6: No clear evidence | B6: Professional | C6: Image does not show strong visual indicators of active colonization at this time. | D6: No mold present. | E6: Preserve professional caution | F6: Visual evidence is limited; continue routine moisture control and reassess if conditions change.
A7: Hard surface spotting | B7: Homeowner | C7: This pattern may be surface residue or growth supported by dust/soap film on a hard surface. | D7: The tile itself is moldy. | E7: Teach substrate logic | F7: These spots may be feeding on residue rather than the tile or glass itself. Clean thoroughly and reduce moisture.
A8: Hard surface spotting | B8: Professional | C8: Appearance is consistent with residue-supported growth on a non-porous surface, pending site context. | D8: Confirmed colonization of non-porous substrate. | E8: Use precise technical framing | F8: Non-porous substrate involvement appears secondary to residue loading; confirm with field context.
A9: Moisture without visible colony | B9: Homeowner | C9: Moisture conditions are present and may support future mold growth. | D9: There is mold here. | E9: Flag risk without overcalling | F9: We see moisture-related warning signs. Address the leak or humidity source and monitor for changes.
A10: Moisture without visible colony | B10: Professional | C10: Moisture indicators are present; visual evidence of active growth is not yet definitive. | D10: Active mold confirmed. | E10: Separate conditions from diagnosis | F10: Conditions are favorable for colonization; inspect source and monitor for progression.
A11: Possible active growth | B11: Homeowner | C11: This image shows patterns that may be consistent with active mold growth. | D11: This is toxic mold. | E11: Maintain caution and avoid medical/legal overreach | F11: The visible texture and moisture pattern raise concern for active growth. A targeted inspection is recommended.
A12: Possible active growth | B12: Professional | C12: Visual findings are consistent with possible active fungal colonization associated with moisture intrusion. | D12: Confirmed toxigenic contamination from image alone. | E12: Use report-ready wording | F12: Findings warrant site inspection, moisture mapping, and substrate evaluation.
A13: High concern / recurring issue | B13: Homeowner | C13: Multiple warning signs suggest this issue should be inspected promptly by a qualified professional. | D13: Your house is unsafe. | E13: Create urgency without fear language | F13: Because the issue appears recurrent and moisture-related, professional inspection is recommended.
A14: High concern / recurring issue | B14: Professional | C14: Combined indicators raise concern for active amplification and a persistent moisture source. | D14: Building-wide contamination confirmed. | E14: Escalate appropriately | F14: Recommend moisture correction, source investigation, and remediation scope based on field findings.

Sheet Moisture Source Classification
A1: Home Health AI – Moisture Source Classification
A2: Use this sheet to classify likely moisture causes behind visible mold or moisture signatures. The AI should infer source likelihood, not overstate certainty.
A4: Source Type | B4: Typical Indicators | C4: Common Rooms | D4: Visual Clues | E4: Risk Pattern | F4: Likely Hidden? | G4: Suggested AI Output | H4: Professional Follow-up
A5: Plumbing leak | B5: Localized wetness, recurring moisture near supply/drain lines | C5: Bathrooms, kitchens, laundry, under sinks | D5: Cabinet base swelling, repeated spotting below fixtures, staining around penetrations | E5: Persistent if leak remains active | F5: High | G5: Possible plumbing-related moisture source | H5: Inspect supply lines, traps, shutoffs, wall cavity if recurring
A6: Roof leak | B6: Ceiling/wall staining after rain, attic-side dampness | C6: Attics, upper ceilings, exterior-adjacent walls | D6: Brown/yellow halos, ceiling texture damage, vertical drip paths | E6: Can worsen seasonally | F6: Moderate-High | G6: Possible roof or flashing intrusion | H6: Inspect roof assembly, attic decking, penetrations, flashing
A7: HVAC condensation | B7: Growth around vents, air handler, drain pans, ducts | C7: Closets, mechanical rooms, ceilings near vents | D7: Black spotting near register boots, condensation sheen, rust marks | E7: Often chronic if drainage/insulation poor | F7: Moderate-High | G7: Possible HVAC condensation source | H7: Check drain pans, line clogs, duct insulation, humidity control
A8: Humidity / condensation | B8: Diffuse spotting on cool surfaces, windows, corners | C8: Bathrooms, bedrooms, exterior walls, closets | D8: Uniform spotting, window track moisture, cold-corner growth | E8: Often seasonal and room-wide | F8: Moderate | G8: High indoor humidity / condensation likely | H8: Check ventilation, RH, thermal bridging, occupant habits
A9: Ground / crawlspace moisture | B9: Lower-wall dampness, musty odor, subfloor concerns | C9: Crawlspaces, lower walls, first-floor closets | D9: Baseboard staining, floor-edge cupping, insulation discoloration | E9: Can spread broadly over time | F9: High | G9: Possible ground moisture or crawlspace contribution | H9: Inspect vapor barrier, drainage, vents, subfloor moisture
A10: Flood / bulk water event | B10: Rapid wetting history, broad material impact | C10: Any room after intrusion | D10: Water line, warped materials, staining and debris patterns | E10: High acute risk | F10: Variable | G10: Past bulk-water event may explain growth conditions | H10: Determine event history, material replacement scope, drying verification
A11: Window / envelope intrusion | B11: Localized staining below windows or exterior penetrations | C11: Bedrooms, living rooms, exterior-facing walls | D11: Streaking below sill, trim swelling, localized drywall discoloration | E11: May recur with weather | F11: Moderate | G11: Possible envelope or window intrusion | H11: Inspect sealants, flashing, cladding transitions
A12: Unknown / mixed | B12: Multiple possible indicators with weak source confidence | C12: Any | D12: Mixed evidence | E12: Needs contextual review | F12: Unknown | G12: Moisture source unclear from image alone | H12: Use site history, moisture mapping, and more images

Sheet Room Inspection Logic
A1: Home Health AI – Room-by-Room Inspection Logic
A2: Use this sheet to tailor AI recommendations to the room context. The same visual pattern can mean different things in a bathroom than in an attic or crawlspace.
A4: Room / Area | B4: Primary Risk Drivers | C4: High-Value Checkpoints | D4: Common False Positives | E4: Escalation Triggers | F4: Homeowner Language | G4: Professional Language | H4: Suggested Next Step | I4: Priority
A5: Bathroom | B5: Humidity, shower condensation, plumbing leaks | C5: Caulk lines, grout, vanity base, toilet seal area, exhaust fan performance | D5: Soap film, mildew on residue, cosmetic staining | E5: Recurring spotting, bubbling drywall, sub-sink moisture | F5: This area often has humidity-related spotting. Improve drying and check for leaks. | G5: Bathroom conditions favor condensation-related growth; evaluate ventilation and concealed plumbing. | H5: Check RH, fan, caulk/grout, plumbing under vanity | I5: Moderate
A6: Kitchen | B6: Sink leaks, dishwasher leaks, icemaker line, poor ventilation | C6: Under sink, behind dishwasher, refrigerator line, backsplash penetrations | D6: Food splatter, grease film, old staining | E6: Recurring cabinet-base swelling, odor, hidden leak history | F6: Kitchen moisture can come from plumbing or appliance lines. Recurring spots should be checked. | G6: Inspect for active or intermittent plumbing/appliance leaks and substrate impact. | H6: Inspect appliance lines and cabinet base; retake images after cleaning | I6: Moderate-High
A7: Laundry | B7: Washer hoses, drain overflow, dryer humidity | C7: Supply hoses, drain standpipe, behind washer, wall base | D7: Detergent residue, lint buildup | E7: Recurring dampness, floor edge damage, musty closet-like odor | F7: Laundry areas can stay damp from hoses or drainage problems. | G7: Assess intermittent discharge, hose integrity, drain overflow risk, and adjacent material wetting. | H7: Inspect hoses, drain line, pan, nearby drywall and flooring | I7: Moderate-High
A8: Bedroom | B8: Window condensation, exterior-wall intrusion, closet stagnation | C8: Window sills, exterior corners, closet walls | D8: Dust, scuffs, shadowing | E8: Cold-corner spotting, repeated window moisture, occupant complaint | F8: Bedrooms can collect condensation on cooler walls or around windows. | G8: Differentiate condensation patterns from envelope intrusion and evaluate closet airflow. | H8: Check windows, RH, airflow, exterior wall temperature | I8: Moderate
A9: Closet | B9: Low airflow, humidity, exterior wall cooling, hidden leaks | C9: Back walls, corners, ceiling-wall joints, adjacent plumbing walls | D9: Dust, fabric transfer, shelf scuffs | E9: Musty odor, recurring back-wall spotting, adjacent bathroom wall | F9: Closets can trap moisture because air does not move well. | G9: Low-airflow space with possible condensation or concealed wall-source contribution. | H9: Improve airflow; inspect adjacent wet walls if recurring | I9: Moderate-High
A10: Attic | B10: Roof intrusion, duct sweating, poor ventilation | C10: Roof decking, insulation, penetrations, duct boots | D10: Old staining, dirt, wood discoloration not microbial | E10: Fresh staining, wet decking, chronic vent-area growth | F10: Attic staining may relate to roof leaks or ventilation issues. | G10: Differentiate historic staining from active wetting; inspect decking moisture and ventilation balance. | H10: Inspect after rain if possible; check ducts and vents | I10: High
A11: Crawlspace | B11: Ground moisture, vapor barrier failure, drainage | C11: Subfloor, joists, insulation, perimeter walls | D11: Soil staining, dirt, construction residue | E11: Musty odor, wood moisture, broad fungal growth pattern | F11: Crawlspaces can hold moisture from the ground for long periods. | G11: Assess vapor control, drainage, ventilation, and structural wood moisture. | H11: Inspect vapor barrier and wood moisture; consider professional crawlspace review | I11: High
A12: HVAC / Mechanical | B12: Condensate leaks, drain pan issues, duct insulation | C12: Air handler, drain lines, plenums, nearby drywall | D12: Dust accumulation, rust, normal grime | E12: Repeated vent spotting, pan overflow, line clogs | F12: Mechanical areas can support growth when condensation is not draining correctly. | G12: Evaluate condensate management, insulation, and localized amplification near supply paths. | H12: Inspect drain pan, line, insulation, surrounding surfaces | I12: High

Sheet Remediation Framework
A1: Home Health AI – Remediation Decision Framework
A2: This framework helps the app distinguish between monitor/clean/escalate pathways. It does not replace a field scope or standard of care.
A4: Scenario | B4: Visual Severity | C4: Substrate Type | D4: Moisture Status | E4: Recurrence | F4: Suggested Path | G4: Homeowner Message | H4: Professional Message | I4: Notes / Limits
A5: Light spotting on hard surface only | B5: Low | C5: Non-porous with residue | D5: No active wetness visible | E5: No | F5: Clean + monitor | G5: Clean the surface thoroughly and watch for return after moisture is controlled. | H5: Likely residue-supported growth; confirm no hidden moisture. | I5: Do not imply substrate colonization from image alone.
A6: Localized spotting on porous material | B6: Moderate | C6: Porous | D6: Possible or prior wetness | E6: Unknown | F6: Targeted inspection | G6: Visible patterns may reflect active growth on an absorbent material. A closer inspection is recommended. | H6: Possible active colonization on porous substrate; inspect source and extent. | I6: Porous materials raise concern even with small visible area.
A7: Recurring growth after cleaning | B7: Moderate-High | C7: Any | D7: Likely ongoing | E7: Yes | F7: Escalate to source investigation | G7: Because the issue keeps returning, the moisture source may still be present. | H7: Recurrence suggests unresolved moisture and possible concealed growth. | I7: Recurrence should materially raise model concern.
A8: Widespread growth + moisture evidence | B8: High | C8: Porous or mixed | D8: Active or likely active | E8: Yes/Unknown | F8: Professional inspection / remediation-oriented pathway | G8: Multiple signs suggest a larger moisture-related issue that should be inspected promptly. | H8: Combined indicators raise concern for active amplification and remediation scoping. | I8: Avoid exact square-foot claims from image alone.
A9: Historic stain without current texture | B9: Low-Moderate | C9: Any | D9: No clear active wetness | E9: No | F9: Monitor / verify history | G9: This may be older staining, but the area should be watched for changes or dampness. | H9: Historic impact possible; verify no current wetting or active colonization. | I9: Encourage follow-up images and history questions.
A10: HVAC vent spotting with condensation signs | B10: Moderate-High | C10: Mixed | D10: Likely active condensation | E10: Often recurring | F10: Inspect mechanical source | G10: This pattern may be related to condensation around the HVAC system. | H10: Evaluate drain, insulation, register boot, and nearby moisture conditions. | I10: Mechanical review often more important than surface cleaning alone.

Sheet Image Label Taxonomy
A1: Home Health AI – Image Label Taxonomy
A2: Use consistent labels for training images so the model can learn visual features, room context, substrate logic, and recommendation pathways.
A4: Label Group | B4: Field Name | C4: Allowed Values / Examples | D4: Purpose | E4: Example Annotation | F4: Data Type | G4: Input or Derived | H4: AI Relevance | I4: Review Note | J4: Source / Context
A5: Image metadata | B5: image_id | C5: unique file ID | D5: Track image across model pipeline | E5: IMG_000123 | F5: Text | G5: Input | H5: High | I5: Required for joins | J5: upload system
A6: Scene context | B6: room_type | C6: bathroom, kitchen, attic, crawlspace, closet, bedroom, laundry, hvac | D6: Add environmental context | E6: bathroom | F6: Categorical | G6: Input | H6: High | I6: Use controlled list | J6: annotator
A7: Substrate | B7: surface_type | C7: drywall, wood, carpet, insulation, tile, metal, glass, plastic | D7: Apply porous vs non-porous logic | E7: drywall | F7: Categorical | G7: Input | H7: High | I7: Controlled vocabulary | J7: annotator
A8: Moisture signal | B8: moisture_visible | C8: 0/1 | D8: Flag visible wetness or sheen | E8: 1 | F8: Binary | G8: Input | H8: High | I8: Needs image evidence | J8: annotator
A9: Visual feature | B9: texture_type | C9: fuzzy, powdery, slimy, dust-like, none | D9: Help classify colony type | E9: fuzzy | F9: Categorical | G9: Input | H9: High | I9: Use best-fit single label if needed | J9: annotator
A10: Visual feature | B10: edge_pattern | C10: circular, diffuse, irregular, linear, speckled | D10: Describe growth geometry | E10: irregular | F10: Categorical | G10: Input | H10: High | I10: Can be multi-label in future | J10: annotator
A11: Visual feature | B11: color_profile | C11: black, green, brown, gray, white, yellow, mixed | D11: Support CV learning | E11: mixed | F11: Categorical | G11: Input | H11: Medium-High | I11: Use dominant visible colors | J11: annotator
A12: Coverage | B12: coverage_band | C12: trace, small, moderate, broad | D12: Approximate severity without exact area claim | E12: small | F12: Ordinal | G12: Derived | H12: Medium | I12: Avoid exact sqft from image | J12: model/annotator
A13: Source inference | B13: likely_source | C13: plumbing, roof, hvac, condensation, crawlspace, unknown | D13: Connect image to probable moisture cause | E13: condensation | F13: Categorical | G13: Derived | H13: High | I13: Inference only, not certainty | J13: model
A14: App output | B14: risk_band | C14: low, guarded, moderate, elevated, high | D14: Standardize response language | E14: moderate | F14: Ordinal | G14: Derived | H14: High | I14: Should align with scoring sheet | J14: model
A15: App output | B15: next_step | C15: monitor, clean, inspect, escalate | D15: Power workflow and CTA | E15: inspect | F15: Categorical | G15: Derived | H15: High | I15: Map to decision tree | J15: model

Sheet Training Annotation Template
A1: Home Health AI – Training Annotation Template
A2: Fill blue cells for each training image. Derived columns calculate basic flags and route toward app output classes.
A4: image_id | B4: room_type | C4: surface_type | D4: moisture_visible (0/1) | E4: texture_type | F4: edge_pattern | G4: color_profile | H4: recurring_issue (0/1) | I4: odor_reported (0/1) | J4: likely_source | K4: derived_substrate_flag | L4: derived_attention_flag
A5: IMG_001 | B5: bathroom | C5: tile | D5: 1 | E5: speckled | F5: diffuse | G5: black | H5: 0 | I5: 0 | J5: condensation | K5: =IF(OR(C5="drywall",C5="wood",C5="carpet",C5="insulation"),"Porous","Hard/Mixed") -> Hard/Mixed | L5: =IF(AND(D5=1,OR(K5="Porous",H5=1,I5=1)),"Escalate","Review / Monitor") -> Review / Monitor
A6: IMG_002 | B6: closet | C6: drywall | D6: 1 | E6: fuzzy | F6: irregular | G6: mixed | H6: 1 | I6: 1 | J6: unknown | K6: =IF(OR(C6="drywall",C6="wood",C6="carpet",C6="insulation"),"Porous","Hard/Mixed") -> Porous | L6: =IF(AND(D6=1,OR(K6="Porous",H6=1,I6=1)),"Escalate","Review / Monitor") -> Escalate
A7: IMG_003 | B7: hvac | C7: metal | D7: 1 | E7: dust-like | F7: linear | G7: black | H7: 1 | I7: 1 | J7: hvac | K7: =IF(OR(C7="drywall",C7="wood",C7="carpet",C7="insulation"),"Porous","Hard/Mixed") -> Hard/Mixed | L7: =IF(AND(D7=1,OR(K7="Porous",H7=1,I7=1)),"Escalate","Review / Monitor") -> Escalate
A8: IMG_004 | B8: attic | C8: wood | D8: 1 | E8: powdery | F8: patchy | G8: brown | H8: 0 | I8: 0 | J8: roof | K8: =IF(OR(C8="drywall",C8="wood",C8="carpet",C8="insulation"),"Porous","Hard/Mixed") -> Porous | L8: =IF(AND(D8=1,OR(K8="Porous",H8=1,I8=1)),"Escalate","Review / Monitor") -> Escalate

Sheet Lab Interpretation Rules
A1: Home Health AI – Lab Interpretation Rules
A2: Condensed rules from the uploaded lab report and interpretation guide for safer AI screening outputs.
A4: Section | B4: Topic | C4: Lab rule / interpretation | D4: AI implication | E4: Example app language | F4: Source file
A5: Air cassette logic | B5: Non-viable spore trap | C5: Air-O-Cell / spore-trap analysis identifies and counts airborne spores by microscopy; it does not culture viability. | D5: Do not claim a photo or air sample proves a live colony without context. | E5: Air data can suggest amplification, but viability and source confirmation may require more inspection. | F5: Lab Information.pdf
A6: Air cassette logic | B6: Indoor vs outdoor comparison | C6: Indoor air is commonly interpreted against an exterior/baseline sample; elevated indoor counts and/or unusual dominance can suggest indoor amplification. | D6: Use comparison logic when air data exists; avoid calling contamination from a single raw number alone. | E6: Indoor levels above baseline can increase concern for indoor amplification. | F6: Lab Information.pdf
A7: Air cassette logic | B7: Count per m³ | C7: Count per cubic meter is calculated from raw count adjusted for sampled air volume. | D7: Store both raw count and count/m³ when using lab examples or QA data. | E7: Standardized count/m³ helps compare samples collected at different volumes. | F7: 21056763_Jaunich_20211020173423.pdf
A8: Air cassette logic | B8: Background debris / density | C8: Higher debris can occlude small spores and make undercounting more likely. | D8: Lower AI confidence when lab notes show heavy background or visibility issues. | E8: Heavy background can hide smaller spores, so findings may under-represent the true load. | F8: Both uploaded PDFs
A9: Air cassette logic | B9: Rain / humidity shift outdoor profile | C9: Rain or high humidity may depress some outdoor spores while increasing ascospores / basidiospores. | D9: Do not over-interpret a wet-day baseline without weather context. | E9: Weather can shift outdoor fungal profiles, especially ascospores and basidiospores. | F9: Lab Information.pdf
A10: Water-damage thresholds | B10: High-moisture indicators | C10: Stachybotrys and Chaetomium are treated as strong water-damage indicators even at relatively low counts. | D10: Escalate concern when these appear with moisture evidence or porous substrates. | E10: Water-damage indicator molds deserve more attention even at lower counts. | F10: 21056763_Jaunich_20211020173423.pdf
A11: Grouping logic | B11: Aspergillus/Penicillium grouping | C11: Small round spores are often reported together on non-viable samples; similar-looking fungi can also fall in that grouped bucket. | D11: Use AI visual groups to avoid false precision from photos or non-viable microscopy. | E11: Some molds look too similar to separate confidently without reproductive structures. | F11: Both uploaded PDFs
A12: Direct ID logic | B12: Evidence-of-growth scale | C12: Direct-ID uses rare / light / moderate / heavy to estimate possible growth based on mycelia and conidiophores. | D12: Map this to confidence and next-step language instead of medical claims. | E12: Surface evidence can be described as limited, possible, probable, or significant growth. | F12: 21056763_Jaunich_20211020173423.pdf
A13: Safety framing | B13: Screening vs diagnosis | C13: Lab reports explicitly avoid declaring building safety from lab data alone. | D13: Keep the app in screening / triage mode, not medical or definitive diagnosis mode. | E13: This tool screens for concern and helps decide whether inspection is warranted. | F13: Both uploaded PDFs
A16: Background Density Scale
A17: Density | B17: Amount of particulate on slide | C17: Interpretation | D17: Occlusion risk | E17: AI confidence adjustment | F17: Source file
A18: 1 | B18: Insignificant | C18: Should not skew counts | D18: Minimal | E18: No penalty | F18: 21056763_Jaunich_20211020173423.pdf
A19: 1+ | B19: Low | C19: Should not skew counts | D19: Low | E19: No penalty | F19: 21056763_Jaunich_20211020173423.pdf
A20: 2 | B20: Low to moderate | C20: Should not skew counts | D20: Low | E20: Small caution only | F20: 21056763_Jaunich_20211020173423.pdf
A21: 2+ | B21: Moderate to high | C21: May occlude small spores | D21: Moderate | E21: Lower confidence slightly | F21: 21056763_Jaunich_20211020173423.pdf
A22: 3 | B22: High | C22: May occlude small to medium spores | D22: High | E22: Lower confidence | F22: 21056763_Jaunich_20211020173423.pdf
A23: 3+ | B23: Very high | C23: Will occlude spores | D23: Very high | E23: Strong confidence penalty | F23: 21056763_Jaunich_20211020173423.pdf
A24: 4 | B24: Overloaded | C24: Too much particulate to perform analysis | D24: Extreme | E24: Treat as unreadable / inconclusive | F24: 21056763_Jaunich_20211020173423.pdf
A27: Direct ID Evidence-of-Growth Scale
A28: Estimated amount | B28: Growth indication | C28: Evidence on sample | D28: Suggested app wording | E28: Escalation posture | F28: Source file
A29: Rare | B29: Not likely | C29: No associated mycelial fragments / conidiophores | D29: Trace evidence only; below clear contamination level | E29: Monitor / inspect if recurring | F29: 21056763_Jaunich_20211020173423.pdf
A30: Light | B30: Possible | C30: Some evidence, about 10–25% of tape covered | D30: Possible active growth | E30: Recommend closer inspection | F30: 21056763_Jaunich_20211020173423.pdf
A31: Moderate | B31: Probable | C31: Abundant evidence, about 25–50% of tape covered | D31: Probable active growth | E31: Professional inspection / remediation discussion | F31: 21056763_Jaunich_20211020173423.pdf
A32: Heavy | B32: Significant | C32: Throughout sample, about 50–100% covered | D32: Significant active growth likely | E32: Escalate strongly | F32: 21056763_Jaunich_20211020173423.pdf

Sheet Lab Sample Examples
A1: Home Health AI – Lab Sample Examples
A2: Structured examples from uploaded SanAir and AEMTEK reports for AI QA, messaging tests, and baseline-vs-interior interpretation.
A4: Air Sample Example Rows
A5: sample_id | B5: sample_location | C5: sample_type | D5: volume_l | E5: background_density | F5: organism | G5: raw_count | H5: count_per_m3 | I5: percent_of_total | J5: ai_interpretation_note
A6: 21056763-001 | B6: Exterior | C6: Air-O-Cell | D6: 75 | E6: 2 | F6: Alternaria species | G6: 2 | H6: 27 | I6: <1% | J6: Exterior baseline outdoor-type detection
A7: 21056763-001 | B7: Exterior | C7: Air-O-Cell | D7: 75 | E7: 2 | F7: Ascospores | G7: 882 | H7: 11760 | I7: 99% | J7: Exterior baseline dominated by ascospores
A8: 21056763-001 | B8: Exterior | C8: Air-O-Cell | D8: 75 | E8: 2 | F8: Chaetomium species | G8: 2 | H8: 27 | I8: <1% | J8: Low-count water-damage indicator outdoors
A9: 21056763-001 | B9: Exterior | C9: Air-O-Cell | D9: 75 | E9: 2 | F9: Cladosporium species | G9: 5 | H9: 67 | I9: <1% | J9: Common outdoor allergen baseline
A10: 21056763-001 | B10: Exterior | C10: Air-O-Cell | D10: 75 | E10: 2 | F10: Non-specified spore | G10: 1 | H10: 13 | I10: <1% | J10: Unspecified trace morphology
A11: 21056763-002 | B11: Entry | C11: Air-O-Cell | D11: 75 | E11: 3+ | F11: Alternaria species | G11: 1 | H11: 13 | I11: <1% | J11: Trace indoor alternaria
A12: 21056763-002 | B12: Entry | C12: Air-O-Cell | D12: 75 | E12: 3+ | F12: Ascospores | G12: 1 | H12: 13 | I12: <1% | J12: Very low ascospores indoors
A13: 21056763-002 | B13: Entry | C13: Air-O-Cell | D13: 75 | E13: 3+ | F13: Basidiospores | G13: >12000 | H13: >160000 | I13: >99% | J13: Heavy indoor basidiospore dominance with very high background
A14: 21056763-002 | B14: Entry | C14: Air-O-Cell | D14: 75 | E14: 3+ | F14: Cladosporium species | G14: 1 | H14: 13 | I14: <1% | J14: Trace cladosporium indoors
A15: 21056763-003 | B15: TV Area | C15: Air-O-Cell | D15: 75 | E15: 3+ | F15: Basidiospores | G15: >12000 | H15: >160000 | I15: >99% | J15: Heavy indoor basidiospore dominance with very high background
A18: Direct ID Example Rows
A19: sample_id | B19: sample_location | C19: sample_material_type | D19: organism_group | E19: estimated_amount | F19: growth_indication | G19: evidence_note | H19: ai_interpretation_note | I19: source_file | J19: project_name
A20: 21056763-004 | B20: Exterior Side | C20: Bulk material | D20: Aspergillus/Penicillium | E20: Rare | F20: Not likely | G20: No clear mycelial / conidiophore evidence threshold | H20: Trace fungal evidence on bulk material | I20: 21056763_Jaunich_20211020173423.pdf | J20: Jaunich
A21: 21056763-004 | B21: Exterior Side | C21: Bulk material | D21: Basidiospores | E21: Moderate | F21: Probable | G21: Abundant evidence range | H21: Probable growth evidence on sampled material | I21: 21056763_Jaunich_20211020173423.pdf | J21: Jaunich
A22: 21056763-005 | B22: Wall At Beam | C22: Bulk material | D22: Aspergillus/Penicillium | E22: Light | F22: Possible | G22: Some evidence range | H22: Possible growth on bulk sample from beam area | I22: 21056763_Jaunich_20211020173423.pdf | J22: Jaunich
A23: 21056763-005 | B23: Wall At Beam | C23: Bulk material | D23: Basidiospores | E23: Light | F23: Possible | G23: Some evidence range | H23: Possible growth on bulk sample from beam area | I23: 21056763_Jaunich_20211020173423.pdf | J23: Jaunich
A24: 21056763-006 | B24: Beam Inside | C24: Bulk material | D24: Basidiospores | E24: Heavy | F24: Significant | G24: Throughout sample | H24: Significant growth evidence on beam sample | I24: 21056763_Jaunich_20211020173423.pdf | J24: Jaunich
A25: 21056763-007 | B25: Window | C25: Bulk material | D25: Basidiospores | E25: Moderate | F25: Probable | G25: Abundant evidence range | H25: Probable growth evidence on window sample | I25: 21056763_Jaunich_20211020173423.pdf | J25: Jaunich
A26: 21056763-007 | B26: Window | C26: Bulk material | D26: Cladosporium species | E26: Rare | F26: Not likely | G26: No clear mycelial / conidiophore evidence threshold | H26: Trace cladosporium evidence on window sample | I26: 21056763_Jaunich_20211020173423.pdf | J26: Jaunich
A28: AEMTEK Air Sample Example Rows
A29: sample_id | B29: sample_location | C29: sample_type | D29: volume_l | E29: background_density | F29: organism | G29: raw_count | H29: count_per_m3 | I29: percent_of_total | J29: ai_interpretation_note
A30: 23671241 | B30: Downstairs Bedroom | C30: Spore Slit Impaction Cassette | D30: 75 | E30: 26-50% | F30: Aspergillus/Penicillium-like | G30: 7 | H30: 91 | I30: 44% | J30: Indoor dominant genus but still below total outdoor load
